2020-09-03 09:21:19,928 - root - INFO - exec_day :2020-09-03, exec_hour :09, exec_minute :21
2020-09-03 09:21:41,965 - root - INFO - exec_day :2020-09-03, exec_hour :09, exec_minute :21
2020-09-03 09:21:50,100 - root - INFO - exec_day :2020-09-03, exec_hour :09, exec_minute :21
2020-09-03 09:21:57,297 - root - INFO - exec_day :2020-09-03, exec_hour :09, exec_minute :21
2020-09-03 09:22:50,505 - root - INFO - exec_day :2020-09-03, exec_hour :09, exec_minute :22
2020-09-03 09:22:50,775 - root - INFO - -------grpc service start--------
2020-09-03 09:22:50,775 - root - INFO - [::1]:9959
2020-09-03 09:23:24,224 - root - INFO - start_get_data, url: 你好啊
2020-09-03 09:23:24,225 - grpc._server - ERROR - Exception calling application: name 'logger' is not defined
Traceback (most recent call last):
  File "/Users/qudian/anaconda3/envs/py37/lib/python3.7/site-packages/grpc/_server.py", line 435, in _call_behavior
    response_or_iterator = behavior(argument, context)
  File "grpc_run.py", line 39, in SendData
    code, audios_data = inference(request.name)
  File "grpc_run.py", line 30, in inference
    data = get_res_by_grpc( grpc_host, text)
  File "/Users/qudian/Desktop/QDServing/qd_serving/app/grpc/grpc_client.py", line 12, in get_res_by_grpc
    logger.info("start_call_grpc, grpc_host: {}, url: {}".format( grpc_host, url ) )
NameError: name 'logger' is not defined
2020-09-03 09:23:31,116 - root - INFO - start_get_data, url: 你好啊
2020-09-03 09:23:31,117 - grpc._server - ERROR - Exception calling application: name 'logger' is not defined
Traceback (most recent call last):
  File "/Users/qudian/anaconda3/envs/py37/lib/python3.7/site-packages/grpc/_server.py", line 435, in _call_behavior
    response_or_iterator = behavior(argument, context)
  File "grpc_run.py", line 39, in SendData
    code, audios_data = inference(request.name)
  File "grpc_run.py", line 30, in inference
    data = get_res_by_grpc( grpc_host, text)
  File "/Users/qudian/Desktop/QDServing/qd_serving/app/grpc/grpc_client.py", line 12, in get_res_by_grpc
    logger.info("start_call_grpc, grpc_host: {}, url: {}".format( grpc_host, url ) )
NameError: name 'logger' is not defined
2020-09-03 09:23:38,382 - root - INFO - start_get_data, url: 你好啊
2020-09-03 09:23:38,382 - grpc._server - ERROR - Exception calling application: name 'logger' is not defined
Traceback (most recent call last):
  File "/Users/qudian/anaconda3/envs/py37/lib/python3.7/site-packages/grpc/_server.py", line 435, in _call_behavior
    response_or_iterator = behavior(argument, context)
  File "grpc_run.py", line 39, in SendData
    code, audios_data = inference(request.name)
  File "grpc_run.py", line 30, in inference
    data = get_res_by_grpc( grpc_host, text)
  File "/Users/qudian/Desktop/QDServing/qd_serving/app/grpc/grpc_client.py", line 12, in get_res_by_grpc
    logger.info("start_call_grpc, grpc_host: {}, url: {}".format( grpc_host, url ) )
NameError: name 'logger' is not defined
2020-09-03 09:25:34,084 - root - INFO - exec_day :2020-09-03, exec_hour :09, exec_minute :25
2020-09-03 09:25:34,311 - root - INFO - -------grpc service start--------
2020-09-03 09:25:34,311 - root - INFO - [::1]:9959
2020-09-03 09:25:36,069 - root - INFO - start_get_data, url: 你好啊
2020-09-03 09:25:36,069 - grpc._server - ERROR - Exception calling application: name 'url' is not defined
Traceback (most recent call last):
  File "/Users/qudian/anaconda3/envs/py37/lib/python3.7/site-packages/grpc/_server.py", line 435, in _call_behavior
    response_or_iterator = behavior(argument, context)
  File "grpc_run.py", line 39, in SendData
    code, audios_data = inference(request.name)
  File "grpc_run.py", line 30, in inference
    data = get_res_by_grpc( grpc_host, text)
  File "/Users/qudian/Desktop/QDServing/qd_serving/app/grpc/grpc_client.py", line 12, in get_res_by_grpc
    logging.info("start_call_grpc, grpc_host: {}, url: {}".format( grpc_host, url ) )
NameError: name 'url' is not defined
2020-09-03 09:26:14,996 - root - INFO - exec_day :2020-09-03, exec_hour :09, exec_minute :26
2020-09-03 09:26:15,208 - root - INFO - -------grpc service start--------
2020-09-03 09:26:15,208 - root - INFO - [::1]:9959
2020-09-03 09:26:16,527 - root - INFO - start_get_data, url: 你好啊
2020-09-03 09:26:16,527 - grpc._server - ERROR - Exception calling application: name 'url' is not defined
Traceback (most recent call last):
  File "/Users/qudian/anaconda3/envs/py37/lib/python3.7/site-packages/grpc/_server.py", line 435, in _call_behavior
    response_or_iterator = behavior(argument, context)
  File "grpc_run.py", line 39, in SendData
    code, audios_data = inference(request.name)
  File "grpc_run.py", line 30, in inference
    data = get_res_by_grpc( grpc_host, text)
  File "/Users/qudian/Desktop/QDServing/qd_serving/app/grpc/grpc_client.py", line 12, in get_res_by_grpc
    logging.info("start_call_grpc, grpc_host: {}, url: {}".format( grpc_host, url ) )
NameError: name 'url' is not defined
2020-09-03 09:26:29,551 - root - INFO - exec_day :2020-09-03, exec_hour :09, exec_minute :26
2020-09-03 09:26:29,769 - root - INFO - -------grpc service start--------
2020-09-03 09:26:29,769 - root - INFO - [::1]:9959
2020-09-03 09:26:31,250 - root - INFO - start_get_data, url: 你好啊
2020-09-03 09:26:31,251 - root - INFO - start_call_grpc, grpc_host: 127.0.0.1:47261, url: 你好啊
2020-09-03 09:26:31,256 - grpc._server - ERROR - Exception calling application: <_InactiveRpcError of RPC that terminated with:
	status = StatusCode.UNAVAILABLE
	details = "failed to connect to all addresses"
	debug_error_string = "{"created":"@1599096391.256061000","description":"Failed to pick subchannel","file":"src/core/ext/filters/client_channel/client_channel.cc","file_line":4090,"referenced_errors":[{"created":"@1599096391.256057000","description":"failed to connect to all addresses","file":"src/core/ext/filters/client_channel/lb_policy/pick_first/pick_first.cc","file_line":394,"grpc_status":14}]}"
>
Traceback (most recent call last):
  File "/Users/qudian/anaconda3/envs/py37/lib/python3.7/site-packages/grpc/_server.py", line 435, in _call_behavior
    response_or_iterator = behavior(argument, context)
  File "grpc_run.py", line 39, in SendData
    code, audios_data = inference(request.name)
  File "grpc_run.py", line 30, in inference
    data = get_res_by_grpc( grpc_host, text)
  File "/Users/qudian/Desktop/QDServing/qd_serving/app/grpc/grpc_client.py", line 17, in get_res_by_grpc
    response = stub.SendData(call_ant_pb2.AntRequest(name=text))
  File "/Users/qudian/anaconda3/envs/py37/lib/python3.7/site-packages/grpc/_channel.py", line 826, in __call__
    return _end_unary_response_blocking(state, call, False, None)
  File "/Users/qudian/anaconda3/envs/py37/lib/python3.7/site-packages/grpc/_channel.py", line 729, in _end_unary_response_blocking
    raise _InactiveRpcError(state)
grpc._channel._InactiveRpcError: <_InactiveRpcError of RPC that terminated with:
	status = StatusCode.UNAVAILABLE
	details = "failed to connect to all addresses"
	debug_error_string = "{"created":"@1599096391.256061000","description":"Failed to pick subchannel","file":"src/core/ext/filters/client_channel/client_channel.cc","file_line":4090,"referenced_errors":[{"created":"@1599096391.256057000","description":"failed to connect to all addresses","file":"src/core/ext/filters/client_channel/lb_policy/pick_first/pick_first.cc","file_line":394,"grpc_status":14}]}"
>
2020-09-03 09:26:38,101 - root - INFO - start_get_data, url: 你好啊
2020-09-03 09:26:38,101 - root - INFO - start_call_grpc, grpc_host: 127.0.0.1:47260, url: 你好啊
2020-09-03 09:26:38,101 - grpc._server - ERROR - Exception calling application: <_InactiveRpcError of RPC that terminated with:
	status = StatusCode.UNAVAILABLE
	details = "failed to connect to all addresses"
	debug_error_string = "{"created":"@1599096398.101684000","description":"Failed to pick subchannel","file":"src/core/ext/filters/client_channel/client_channel.cc","file_line":4090,"referenced_errors":[{"created":"@1599096398.101683000","description":"failed to connect to all addresses","file":"src/core/ext/filters/client_channel/lb_policy/pick_first/pick_first.cc","file_line":394,"grpc_status":14}]}"
>
Traceback (most recent call last):
  File "/Users/qudian/anaconda3/envs/py37/lib/python3.7/site-packages/grpc/_server.py", line 435, in _call_behavior
    response_or_iterator = behavior(argument, context)
  File "grpc_run.py", line 39, in SendData
    code, audios_data = inference(request.name)
  File "grpc_run.py", line 30, in inference
    data = get_res_by_grpc( grpc_host, text)
  File "/Users/qudian/Desktop/QDServing/qd_serving/app/grpc/grpc_client.py", line 17, in get_res_by_grpc
    response = stub.SendData(call_ant_pb2.AntRequest(name=text))
  File "/Users/qudian/anaconda3/envs/py37/lib/python3.7/site-packages/grpc/_channel.py", line 826, in __call__
    return _end_unary_response_blocking(state, call, False, None)
  File "/Users/qudian/anaconda3/envs/py37/lib/python3.7/site-packages/grpc/_channel.py", line 729, in _end_unary_response_blocking
    raise _InactiveRpcError(state)
grpc._channel._InactiveRpcError: <_InactiveRpcError of RPC that terminated with:
	status = StatusCode.UNAVAILABLE
	details = "failed to connect to all addresses"
	debug_error_string = "{"created":"@1599096398.101684000","description":"Failed to pick subchannel","file":"src/core/ext/filters/client_channel/client_channel.cc","file_line":4090,"referenced_errors":[{"created":"@1599096398.101683000","description":"failed to connect to all addresses","file":"src/core/ext/filters/client_channel/lb_policy/pick_first/pick_first.cc","file_line":394,"grpc_status":14}]}"
>
2020-09-03 09:28:16,549 - root - INFO - exec_day :2020-09-03, exec_hour :09, exec_minute :28
2020-09-03 09:28:16,918 - root - INFO - -------grpc service start--------
2020-09-03 09:28:16,918 - root - INFO - [::1]:9959
2020-09-03 09:28:18,002 - root - INFO - start_get_data, url: 你好啊
2020-09-03 09:28:18,002 - root - INFO - start_call_grpc, grpc_host: 127.0.0.1:47260, url: 你好啊
2020-09-03 09:28:18,007 - grpc._server - ERROR - Exception calling application: <_InactiveRpcError of RPC that terminated with:
	status = StatusCode.UNAVAILABLE
	details = "failed to connect to all addresses"
	debug_error_string = "{"created":"@1599096498.007410000","description":"Failed to pick subchannel","file":"src/core/ext/filters/client_channel/client_channel.cc","file_line":4090,"referenced_errors":[{"created":"@1599096498.007409000","description":"failed to connect to all addresses","file":"src/core/ext/filters/client_channel/lb_policy/pick_first/pick_first.cc","file_line":394,"grpc_status":14}]}"
>
Traceback (most recent call last):
  File "/Users/qudian/anaconda3/envs/py37/lib/python3.7/site-packages/grpc/_server.py", line 435, in _call_behavior
    response_or_iterator = behavior(argument, context)
  File "grpc_run.py", line 39, in SendData
    code, audios_data = inference(request.name)
  File "grpc_run.py", line 30, in inference
    data = get_res_by_grpc( grpc_host, text)
  File "/Users/qudian/Desktop/QDServing/qd_serving/app/grpc/grpc_client.py", line 17, in get_res_by_grpc
    response = stub.SendData(call_ant_pb2.AntRequest(name=text))
  File "/Users/qudian/anaconda3/envs/py37/lib/python3.7/site-packages/grpc/_channel.py", line 826, in __call__
    return _end_unary_response_blocking(state, call, False, None)
  File "/Users/qudian/anaconda3/envs/py37/lib/python3.7/site-packages/grpc/_channel.py", line 729, in _end_unary_response_blocking
    raise _InactiveRpcError(state)
grpc._channel._InactiveRpcError: <_InactiveRpcError of RPC that terminated with:
	status = StatusCode.UNAVAILABLE
	details = "failed to connect to all addresses"
	debug_error_string = "{"created":"@1599096498.007410000","description":"Failed to pick subchannel","file":"src/core/ext/filters/client_channel/client_channel.cc","file_line":4090,"referenced_errors":[{"created":"@1599096498.007409000","description":"failed to connect to all addresses","file":"src/core/ext/filters/client_channel/lb_policy/pick_first/pick_first.cc","file_line":394,"grpc_status":14}]}"
>
2020-09-03 09:28:19,563 - root - INFO - start_get_data, url: 你好啊
2020-09-03 09:28:19,563 - root - INFO - start_call_grpc, grpc_host: 127.0.0.1:47260, url: 你好啊
2020-09-03 09:28:19,564 - grpc._server - ERROR - Exception calling application: <_InactiveRpcError of RPC that terminated with:
	status = StatusCode.UNAVAILABLE
	details = "failed to connect to all addresses"
	debug_error_string = "{"created":"@1599096499.564107000","description":"Failed to pick subchannel","file":"src/core/ext/filters/client_channel/client_channel.cc","file_line":4090,"referenced_errors":[{"created":"@1599096499.564105000","description":"failed to connect to all addresses","file":"src/core/ext/filters/client_channel/lb_policy/pick_first/pick_first.cc","file_line":394,"grpc_status":14}]}"
>
Traceback (most recent call last):
  File "/Users/qudian/anaconda3/envs/py37/lib/python3.7/site-packages/grpc/_server.py", line 435, in _call_behavior
    response_or_iterator = behavior(argument, context)
  File "grpc_run.py", line 39, in SendData
    code, audios_data = inference(request.name)
  File "grpc_run.py", line 30, in inference
    data = get_res_by_grpc( grpc_host, text)
  File "/Users/qudian/Desktop/QDServing/qd_serving/app/grpc/grpc_client.py", line 17, in get_res_by_grpc
    response = stub.SendData(call_ant_pb2.AntRequest(name=text))
  File "/Users/qudian/anaconda3/envs/py37/lib/python3.7/site-packages/grpc/_channel.py", line 826, in __call__
    return _end_unary_response_blocking(state, call, False, None)
  File "/Users/qudian/anaconda3/envs/py37/lib/python3.7/site-packages/grpc/_channel.py", line 729, in _end_unary_response_blocking
    raise _InactiveRpcError(state)
grpc._channel._InactiveRpcError: <_InactiveRpcError of RPC that terminated with:
	status = StatusCode.UNAVAILABLE
	details = "failed to connect to all addresses"
	debug_error_string = "{"created":"@1599096499.564107000","description":"Failed to pick subchannel","file":"src/core/ext/filters/client_channel/client_channel.cc","file_line":4090,"referenced_errors":[{"created":"@1599096499.564105000","description":"failed to connect to all addresses","file":"src/core/ext/filters/client_channel/lb_policy/pick_first/pick_first.cc","file_line":394,"grpc_status":14}]}"
>
2020-09-03 09:28:39,378 - root - INFO - exec_day :2020-09-03, exec_hour :09, exec_minute :28
2020-09-03 09:28:39,654 - root - INFO - -------grpc service start--------
2020-09-03 09:28:39,654 - root - INFO - [::1]:9959
2020-09-03 09:28:41,431 - root - INFO - start_get_data, url: 你好啊
2020-09-03 09:28:41,431 - root - INFO - start_call_grpc, grpc_host: localhost:47260, url: 你好啊
2020-09-03 09:28:41,443 - root - INFO - success_data_by_grpc, time: 0.012027263641357422s, size: 3, url: 你好啊
2020-09-03 09:28:41,443 - root - ERROR - fail_get_data, time: 0.012329816818237305s, data_size: 3, url: 你好啊
2020-09-03 09:28:42,973 - root - INFO - start_get_data, url: 你好啊
2020-09-03 09:28:42,973 - root - INFO - start_call_grpc, grpc_host: localhost:47260, url: 你好啊
2020-09-03 09:28:42,975 - root - INFO - success_data_by_grpc, time: 0.0018889904022216797s, size: 3, url: 你好啊
2020-09-03 09:28:42,976 - root - ERROR - fail_get_data, time: 0.00220489501953125s, data_size: 3, url: 你好啊
2020-09-03 09:28:44,357 - root - INFO - start_get_data, url: 你好啊
2020-09-03 09:28:44,357 - root - INFO - start_call_grpc, grpc_host: localhost:47260, url: 你好啊
2020-09-03 09:28:44,359 - root - INFO - success_data_by_grpc, time: 0.0016021728515625s, size: 3, url: 你好啊
2020-09-03 09:28:44,359 - root - ERROR - fail_get_data, time: 0.0018482208251953125s, data_size: 3, url: 你好啊
2020-09-03 09:29:26,898 - root - INFO - exec_day :2020-09-03, exec_hour :09, exec_minute :29
2020-09-03 09:29:27,349 - werkzeug - INFO -  * Running on http://0.0.0.0:9959/ (Press CTRL+C to quit)
2020-09-03 09:29:27,350 - werkzeug - INFO -  * Restarting with stat
2020-09-03 09:29:27,397 - root - INFO - exec_day :2020-09-03, exec_hour :09, exec_minute :29
2020-09-03 09:29:27,731 - werkzeug - WARNING -  * Debugger is active!
2020-09-03 09:29:27,741 - werkzeug - INFO -  * Debugger PIN: 288-578-517
2020-09-03 09:30:43,026 - werkzeug - INFO -  * Detected change in '/Users/qudian/Desktop/QDServing/qd_serving/app/core/search.py', reloading
2020-09-03 09:30:43,062 - werkzeug - INFO -  * Restarting with stat
2020-09-03 09:30:43,114 - root - INFO - exec_day :2020-09-03, exec_hour :09, exec_minute :30
2020-09-03 09:30:43,492 - werkzeug - WARNING -  * Debugger is active!
2020-09-03 09:30:43,499 - werkzeug - INFO -  * Debugger PIN: 288-578-517
2020-09-03 09:30:44,517 - werkzeug - INFO -  * Detected change in '/Users/qudian/Desktop/QDServing/qd_serving/app/core/search.py', reloading
2020-09-03 09:30:44,551 - werkzeug - INFO -  * Restarting with stat
2020-09-03 09:30:44,602 - root - INFO - exec_day :2020-09-03, exec_hour :09, exec_minute :30
2020-09-03 09:30:44,941 - werkzeug - WARNING -  * Debugger is active!
2020-09-03 09:30:44,946 - werkzeug - INFO -  * Debugger PIN: 288-578-517
2020-09-03 09:31:02,666 - root - INFO - [TTSInference] [post] request.json:{'content': ''}
2020-09-03 09:31:02,666 - root - INFO - [TTSInference] [post] text:
2020-09-03 09:31:02,666 - root - INFO - start_call_grpc, grpc_host: localhost:47260, url: 
2020-09-03 09:31:02,675 - root - INFO - success_data_by_grpc, time: 0.008919000625610352s, size: 0, url: 
2020-09-03 09:31:02,676 - werkzeug - INFO - 127.0.0.1 - - [03/Sep/2020 09:31:02] "[37mPOST /infer HTTP/1.1[0m" 200 -
2020-09-03 09:31:13,735 - root - INFO - [TTSInference] [post] request.json:{'content': '你好啊'}
2020-09-03 09:31:13,735 - root - INFO - [TTSInference] [post] text:你好啊
2020-09-03 09:31:13,735 - root - INFO - start_call_grpc, grpc_host: localhost:47260, url: 你好啊
2020-09-03 09:31:13,737 - root - INFO - success_data_by_grpc, time: 0.0018639564514160156s, size: 3, url: 你好啊
2020-09-03 09:31:13,737 - werkzeug - INFO - 127.0.0.1 - - [03/Sep/2020 09:31:13] "[37mPOST /infer HTTP/1.1[0m" 200 -
